Workbook

Sheet raw data
A1: PO_ID,Supplier,Order_Date,Delivery_Date,Item_Category,Order_Status,Quantity,Unit_Price,Negotiated_Price,Defective_Units,Compliance
A2: PO-00001,Alpha_Inc,2023-10-17,2023-10-25,Office Supplies,Cancelled,1176,20.13,17.81,,Yes
A3: PO-00002,Delta_Logistics,2022-04-25,2022-05-05,Office Supplies,Delivered,1509,39.32,37.34,235.0,Yes
A4: PO-00003,Gamma_Co,2022-01-26,2022-02-15,MRO,Delivered,910,95.51,92.26,41.0,Yes
A5: PO-00004,Beta_Supplies,2022-10-09,2022-10-28,Packaging,Delivered,1344,99.85,95.52,112.0,Yes
A6: PO-00005,Delta_Logistics,2022-09-08,2022-09-20,Raw Materials,Delivered,1180,64.07,60.53,171.0,No
A7: PO-00006,Epsilon_Group,2022-08-17,2022-08-29,MRO,Delivered,1145,69.21,63.57,39.0,Yes
A8: PO-00007,Gamma_Co,2022-05-23,2022-06-03,MRO,Delivered,1774,51.37,47.82,96.0,No
A9: PO-00008,Alpha_Inc,2022-04-15,2022-04-29,MRO,Delivered,1094,36.93,32.78,22.0,Yes
A10: PO-00009,Gamma_Co,2023-11-24,2023-11-28,Raw Materials,Partially Delivered,1688,43.93,39.89,89.0,Yes
A11: PO-00010,Gamma_Co,2023-07-13,2023-07-25,Raw Materials,Pending,171,76.87,70.2,8.0,Yes
A12: PO-00011,Epsilon_Group,2022-03-31,2022-04-15,Raw Materials,Delivered,5000,78.49,73.68,18.0,Yes
... A778: PO-00777,Beta_Supplies,2023-12-09,2023-12-11,Office Supplies,Delivered,1988,105.2,93.23,187.0,Yes

Sheet Procurement Dataset
A1: PO_ID | B1: Supplier | C1: Order_Date | D1: New_Delivery_Date | E1: Delivery_Date | F1: Item_Category | G1: Order_Status | H1: Quantity | I1: Unit_Price | J1: Negotiated_Price | K1: New_Defective_Units | L1: Defective_Units | M1: Compliance | N1: Lead_day | O1: validation | P1: Ontime_Status | Q1: Total_Amount | R1: Total_Negotiated | S1: diff_price | T1: is_ontime
A2: PO-00001 | B2: Alpha_Inc | C2: 45216 | D2: =IF(E2="",C2+VLOOKUP(B2,Lembar2!$B$19:$C$24,2,FALSE),'Procurement Dataset'!E2) -> 45224 | E2: 45224 | F2: Office Supplies | G2: Cancelled | H2: 1176 | I2: 20.13 | J2: 17.81 | K2: =IF(L2="", 0, L2) -> 0 | M2: Yes | N2: =IF(E2 = "", "", E2-C2) -> 8 | O2: =IF(D2<C2,"Invalid","Valid") -> Valid | P2: =IF(N2>=(VLOOKUP(B2,Lembar2!$B$19:$C$24,2,FALSE)+7),"Delayed","Ontime") -> Ontime | Q2: =H2*I2 -> 23672.88 | R2: =H2*J2 -> 20944.56 | S2: =Q2-R2 -> 2728.32 | T2: =IF(P2="Ontime",1,0) -> 1
A3: PO-00002 | B3: Delta_Logistics | C3: 44676 | D3: =IF(E3="",C3+VLOOKUP(B3,Lembar2!$B$19:$C$24,2,FALSE),'Procurement Dataset'!E3) -> 44686 | E3: 44686 | F3: Office Supplies | G3: Delivered | H3: 1509 | I3: 39.32 | J3: 37.34 | K3: =IF(L3="", 0, L3) -> 235 | L3: 235 | M3: Yes | N3: =IF(E3 = "", "", E3-C3) -> 10 | O3: =IF(D3<C3,"Invalid","Valid") -> Valid | P3: =IF(N3>=(VLOOKUP(B3,Lembar2!$B$19:$C$24,2,FALSE)+7),"Delayed","Ontime") -> Ontime | Q3: =H3*I3 -> 59333.88 | R3: =H3*J3 -> 56346.06 | S3: =Q3-R3 -> 2987.82 | T3: =IF(P3="Ontime",1,0) -> 1
A4: PO-00003 | B4: Gamma_Co | C4: 44587 | D4: =IF(E4="",C4+VLOOKUP(B4,Lembar2!$B$19:$C$24,2,FALSE),'Procurement Dataset'!E4) -> 44607 | E4: 44607 | F4: MRO | G4: Delivered | H4: 910 | I4: 95.51 | J4: 92.26 | K4: =IF(L4="", 0, L4) -> 41 | L4: 41 | M4: Yes | N4: =IF(E4 = "", "", E4-C4) -> 20 | O4: =IF(D4<C4,"Invalid","Valid") -> Valid | P4: =IF(N4>=(VLOOKUP(B4,Lembar2!$B$19:$C$24,2,FALSE)+7),"Delayed","Ontime") -> Delayed | Q4: =H4*I4 -> 86914.1 | R4: =H4*J4 -> 83956.6 | S4: =Q4-R4 -> 2957.5 | T4: =IF(P4="Ontime",1,0) -> 0
A5: PO-00004 | B5: Beta_Supplies | C5: 44843 | D5: =IF(E5="",C5+VLOOKUP(B5,Lembar2!$B$19:$C$24,2,FALSE),'Procurement Dataset'!E5) -> 44862 | E5: 44862 | F5: Packaging | G5: Delivered | H5: 1344 | I5: 99.85 | J5: 95.52 | K5: =IF(L5="", 0, L5) -> 112 | L5: 112 | M5: Yes | N5: =IF(E5 = "", "", E5-C5) -> 19 | O5: =IF(D5<C5,"Invalid","Valid") -> Valid | P5: =IF(N5>=(VLOOKUP(B5,Lembar2!$B$19:$C$24,2,FALSE)+7),"Delayed","Ontime") -> Delayed | Q5: =H5*I5 -> 134198.4 | R5: =H5*J5 -> 128378.88 | S5: =Q5-R5 -> 5819.52 | T5: =IF(P5="Ontime",1,0) -> 0
A6: PO-00005 | B6: Delta_Logistics | C6: 44812 | D6: =IF(E6="",C6+VLOOKUP(B6,Lembar2!$B$19:$C$24,2,FALSE),'Procurement Dataset'!E6) -> 44824 | E6: 44824 | F6: Raw Materials | G6: Delivered | H6: 1180 | I6: 64.07 | J6: 60.53 | K6: =IF(L6="", 0, L6) -> 171 | L6: 171 | M6: No | N6: =IF(E6 = "", "", E6-C6) -> 12 | O6: =IF(D6<C6,"Invalid","Valid") -> Valid | P6: =IF(N6>=(VLOOKUP(B6,Lembar2!$B$19:$C$24,2,FALSE)+7),"Delayed","Ontime") -> Ontime | Q6: =H6*I6 -> 75602.6 | R6: =H6*J6 -> 71425.4 | S6: =Q6-R6 -> 4177.2 | T6: =IF(P6="Ontime",1,0) -> 1
A7: PO-00006 | B7: Epsilon_Group | C7: 44790 | D7: =IF(E7="",C7+VLOOKUP(B7,Lembar2!$B$19:$C$24,2,FALSE),'Procurement Dataset'!E7) -> 44802 | E7: 44802 | F7: MRO | G7: Delivered | H7: 1145 | I7: 69.21 | J7: 63.57 | K7: =IF(L7="", 0, L7) -> 39 | L7: 39 | M7: Yes | N7: =IF(E7 = "", "", E7-C7) -> 12 | O7: =IF(D7<C7,"Invalid","Valid") -> Valid | P7: =IF(N7>=(VLOOKUP(B7,Lembar2!$B$19:$C$24,2,FALSE)+7),"Delayed","Ontime") -> Ontime | Q7: =H7*I7 -> 79245.45 | R7: =H7*J7 -> 72787.65 | S7: =Q7-R7 -> 6457.8 | T7: =IF(P7="Ontime",1,0) -> 1
A8: PO-00007 | B8: Gamma_Co | C8: 44704 | D8: =IF(E8="",C8+VLOOKUP(B8,Lembar2!$B$19:$C$24,2,FALSE),'Procurement Dataset'!E8) -> 44715 | E8: 44715 | F8: MRO | G8: Delivered | H8: 1774 | I8: 51.37 | J8: 47.82 | K8: =IF(L8="", 0, L8) -> 96 | L8: 96 | M8: No | N8: =IF(E8 = "", "", E8-C8) -> 11 | O8: =IF(D8<C8,"Invalid","Valid") -> Valid | P8: =IF(N8>=(VLOOKUP(B8,Lembar2!$B$19:$C$24,2,FALSE)+7),"Delayed","Ontime") -> Ontime | Q8: =H8*I8 -> 91130.38 | R8: =H8*J8 -> 84832.68 | S8: =Q8-R8 -> 6297.7 | T8: =IF(P8="Ontime",1,0) -> 1
A9: PO-00008 | B9: Alpha_Inc | C9: 44666 | D9: =IF(E9="",C9+VLOOKUP(B9,Lembar2!$B$19:$C$24,2,FALSE),'Procurement Dataset'!E9) -> 44680 | E9: 44680 | F9: MRO | G9: Delivered | H9: 1094 | I9: 36.93 | J9: 32.78 | K9: =IF(L9="", 0, L9) -> 22 | L9: 22 | M9: Yes | N9: =IF(E9 = "", "", E9-C9) -> 14 | O9: =IF(D9<C9,"Invalid","Valid") -> Valid | P9: =IF(N9>=(VLOOKUP(B9,Lembar2!$B$19:$C$24,2,FALSE)+7),"Delayed","Ontime") -> Ontime | Q9: =H9*I9 -> 40401.42 | R9: =H9*J9 -> 35861.32 | S9: =Q9-R9 -> 4540.1 | T9: =IF(P9="Ontime",1,0) -> 1
A10: PO-00009 | B10: Gamma_Co | C10: 45254 | D10: =IF(E10="",C10+VLOOKUP(B10,Lembar2!$B$19:$C$24,2,FALSE),'Procurement Dataset'!E10) -> 45258 | E10: 45258 | F10: Raw Materials | G10: Partially Delivered | H10: 1688 | I10: 43.93 | J10: 39.89 | K10: =IF(L10="", 0, L10) -> 89 | L10: 89 | M10: Yes | N10: =IF(E10 = "", "", E10-C10) -> 4 | O10: =IF(D10<C10,"Invalid","Valid") -> Valid | P10: =IF(N10>=(VLOOKUP(B10,Lembar2!$B$19:$C$24,2,FALSE)+7),"Delayed","Ontime") -> Ontime | Q10: =H10*I10 -> 74153.84 | R10: =H10*J10 -> 67334.32 | S10: =Q10-R10 -> 6819.52 | T10: =IF(P10="Ontime",1,0) -> 1
A11: PO-00010 | B11: Gamma_Co | C11: 45120 | D11: =IF(E11="",C11+VLOOKUP(B11,Lembar2!$B$19:$C$24,2,FALSE),'Procurement Dataset'!E11) -> 45132 | E11: 45132 | F11: Raw Materials | G11: Pending | H11: 171 | I11: 76.87 | J11: 70.2 | K11: =IF(L11="", 0, L11) -> 8 | L11: 8 | M11: Yes | N11: =IF(E11 = "", "", E11-C11) -> 12 | O11: =IF(D11<C11,"Invalid","Valid") -> Valid | P11: =IF(N11>=(VLOOKUP(B11,Lembar2!$B$19:$C$24,2,FALSE)+7),"Delayed","Ontime") -> Ontime | Q11: =H11*I11 -> 13144.77 | R11: =H11*J11 -> 12004.2 | S11: =Q11-R11 -> 1140.57 | T11: =IF(P11="Ontime",1,0) -> 1
A12: PO-00011 | B12: Epsilon_Group | C12: 44651 | D12: =IF(E12="",C12+VLOOKUP(B12,Lembar2!$B$19:$C$24,2,FALSE),'Procurement Dataset'!E12) -> 44666 | E12: 44666 | F12: Raw Materials | G12: Delivered | H12: 5000 | I12: 78.49 | J12: 73.68 | K12: =IF(L12="", 0, L12) -> 18 | L12: 18 | M12: Yes | N12: =IF(E12 = "", "", E12-C12) -> 15 | O12: =IF(D12<C12,"Invalid","Valid") -> Valid | P12: =IF(N12>=(VLOOKUP(B12,Lembar2!$B$19:$C$24,2,FALSE)+7),"Delayed","Ontime") -> Ontime | Q12: =H12*I12 -> 392450 | R12: =H12*J12 -> 368400 | S12: =Q12-R12 -> 24050 | T12: =IF(P12="Ontime",1,0) -> 1
A13: PO-00012 | B13: Beta_Supplies | C13: 45166 | D13: =IF(E13="",C13+VLOOKUP(B13,Lembar2!$B$19:$C$24,2,FALSE),'Procurement Dataset'!E13) -> 45180 | E13: 45180 | F13: Raw Materials | G13: Delivered | H13: 5000 | I13: 88.96 | J13: 86.58 | K13: =IF(L13="", 0, L13) -> 115 | L13: 115 | M13: Yes | N13: =IF(E13 = "", "", E13-C13) -> 14 | O13: =IF(D13<C13,"Invalid","Valid") -> Valid | P13: =IF(N13>=(VLOOKUP(B13,Lembar2!$B$19:$C$24,2,FALSE)+7),"Delayed","Ontime") -> Ontime | Q13: =H13*I13 -> 444800 | R13: =H13*J13 -> 432900 | S13: =Q13-R13 -> 11900 | T13: =IF(P13="Ontime",1,0) -> 1
A14: PO-00013 | B14: Beta_Supplies | C14: 44994 | D14: =IF(E14="",C14+VLOOKUP(B14,Lembar2!$B$19:$C$24,2,FALSE),'Procurement Dataset'!E14) -> 45011 | E14: 45011 | F14: Electronics | G14: Pending | H14: 5000 | I14: 86.74 | J14: 74.86 | K14: =IF(L14="", 0, L14) -> 51 | L14: 51 | M14: Yes | N14: =IF(E14 = "", "", E14-C14) -> 17 | O14: =IF(D14<C14,"Invalid","Valid") -> Valid | P14: =IF(N14>=(VLOOKUP(B14,Lembar2!$B$19:$C$24,2,FALSE)+7),"Delayed","Ontime") -> Ontime | Q14: =H14*I14 -> 433700 | R14: =H14*J14 -> 374300 | S14: =Q14-R14 -> 59400 | T14: =IF(P14="Ontime",1,0) -> 1
A15: PO-00014 | B15: Beta_Supplies | C15: 44594 | D15: =IF(E15="",C15+VLOOKUP(B15,Lembar2!$B$19:$C$24,2,FALSE),'Procurement Dataset'!E15) -> 44606 | F15: MRO | G15: Delivered | H15: 5000 | I15: 18.3 | J15: 16.88 | K15: =IF(L15="", 0, L15) -> 0 | M15: Yes | N15: =IF(E15 = "", "", E15-C15) | O15: =IF(D15<C15,"Invalid","Valid") -> Valid | P15: =IF(N15>=(VLOOKUP(B15,Lembar2!$B$19:$C$24,2,FALSE)+7),"Delayed","Ontime") -> Delayed | Q15: =H15*I15 -> 91500 | R15: =H15*J15 -> 84400 | S15: =Q15-R15 -> 7100 | T15: =IF(P15="Ontime",1,0) -> 0
A16: PO-00015 | B16: Delta_Logistics | C16: 44592 | D16: =IF(E16="",C16+VLOOKUP(B16,Lembar2!$B$19:$C$24,2,FALSE),'Procurement Dataset'!E16) -> 44610 | E16: 44610 | F16: Electronics | G16: Pending | H16: 5000 | I16: 54.5 | J16: 48.45 | K16: =IF(L16="", 0, L16) -> 22 | L16: 22 | M16: Yes | N16: =IF(E16 = "", "", E16-C16) -> 18 | O16: =IF(D16<C16,"Invalid","Valid") -> Valid | P16: =IF(N16>=(VLOOKUP(B16,Lembar2!$B$19:$C$24,2,FALSE)+7),"Delayed","Ontime") -> Delayed | Q16: =H16*I16 -> 272500 | R16: =H16*J16 -> 242250 | S16: =Q16-R16 -> 30250 | T16: =IF(P16="Ontime",1,0) -> 0
A17: PO-00016 | B17: Beta_Supplies | C17: 44657 | D17: =IF(E17="",C17+VLOOKUP(B17,Lembar2!$B$19:$C$24,2,FALSE),'Procurement Dataset'!E17) -> 44672 | E17: 44672 | F17: Packaging | G17: Delivered | H17: 5000 | I17: 15.41 | J17: 15.12 | K17: =IF(L17="", 0, L17) -> 0 | M17: Yes | N17: =IF(E17 = "", "", E17-C17) -> 15 | O17: =IF(D17<C17,"Invalid","Valid") -> Valid | P17: =IF(N17>=(VLOOKUP(B17,Lembar2!$B$19:$C$24,2,FALSE)+7),"Delayed","Ontime") -> Ontime | Q17: =H17*I17 -> 77050 | R17: =H17*J17 -> 75600 | S17: =Q17-R17 -> 1450 | T17: =IF(P17="Ontime",1,0) -> 1
A18: PO-00017 | B18: Delta_Logistics | C18: 44785 | D18: =IF(E18="",C18+VLOOKUP(B18,Lembar2!$B$19:$C$24,2,FALSE),'Procurement Dataset'!E18) -> 44804 | E18: 44804 | F18: MRO | G18: Delivered | H18: 1173 | I18: 61.54 | J18: 55.49 | K18: =IF(L18="", 0, L18) -> 172 | L18: 172 | M18: No | N18: =IF(E18 = "", "", E18-C18) -> 19 | O18: =IF(D18<C18,"Invalid","Valid") -> Valid | P18: =IF(N18>=(VLOOKUP(B18,Lembar2!$B$19:$C$24,2,FALSE)+7),"Delayed","Ontime") -> Delayed | Q18: =H18*I18 -> 72186.42 | R18: =H18*J18 -> 65089.77 | S18: =Q18-R18 -> 7096.65 | T18: =IF(P18="Ontime",1,0) -> 0
A19: PO-00018 | B19: Epsilon_Group | C19: 44800 | D19: =IF(E19="",C19+VLOOKUP(B19,Lembar2!$B$19:$C$24,2,FALSE),'Procurement Dataset'!E19) -> 44808 | E19: 44808 | F19: Raw Materials | G19: Delivered | H19: 921 | I19: 51.48 | J19: 50.61 | K19: =IF(L19="", 0, L19) -> 0 | M19: Yes | N19: =IF(E19 = "", "", E19-C19) -> 8 | O19: =IF(D19<C19,"Invalid","Valid") -> Valid | P19: =IF(N19>=(VLOOKUP(B19,Lembar2!$B$19:$C$24,2,FALSE)+7),"Delayed","Ontime") -> Ontime | Q19: =H19*I19 -> 47413.08 | R19: =H19*J19 -> 46611.81 | S19: =Q19-R19 -> 801.27 | T19: =IF(P19="Ontime",1,0) -> 1
A20: PO-00019 | B20: Gamma_Co | C20: 45079 | D20: =IF(E20="",C20+VLOOKUP(B20,Lembar2!$B$19:$C$24,2,FALSE),'Procurement Dataset'!E20) -> 45082 | E20: 45082 | F20: Raw Materials | G20: Partially Delivered | H20: 1737 | I20: 97.53 | J20: 87.37 | K20: =IF(L20="", 0, L20) -> 79 | L20: 79 | M20: Yes | N20: =IF(E20 = "", "", E20-C20) -> 3 | O20: =IF(D20<C20,"Invalid","Valid") -> Valid | P20: =IF(N20>=(VLOOKUP(B20,Lembar2!$B$19:$C$24,2,FALSE)+7),"Delayed","Ontime") -> Ontime | Q20: =H20*I20 -> 169409.61 | R20: =H20*J20 -> 151761.69 | S20: =Q20-R20 -> 17647.92 | T20: =IF(P20="Ontime",1,0) -> 1
A21: PO-00020 | B21: Delta_Logistics | C21: 45178 | D21: =IF(E21="",C21+VLOOKUP(B21,Lembar2!$B$19:$C$24,2,FALSE),'Procurement Dataset'!E21) -> 45193 | E21: 45193 | F21: Raw Materials | G21: Delivered | H21: 180 | I21: 45.74 | J21: 38.89 | K21: =IF(L21="", 0, L21) -> 0 | M21: No | N21: =IF(E21 = "", "", E21-C21) -> 15 | O21: =IF(D21<C21,"Invalid","Valid") -> Valid | P21: =IF(N21>=(VLOOKUP(B21,Lembar2!$B$19:$C$24,2,FALSE)+7),"Delayed","Ontime") -> Ontime | Q21: =H21*I21 -> 8233.2 | R21: =H21*J21 -> 7000.2 | S21: =Q21-R21 -> 1233 | T21: =IF(P21="Ontime",1,0) -> 1
A22: PO-00021 | B22: Epsilon_Group | C22: 44589 | D22: =IF(E22="",C22+VLOOKUP(B22,Lembar2!$B$19:$C$24,2,FALSE),'Procurement Dataset'!E22) -> 44604 | E22: 44604 | F22: Electronics | G22: Cancelled | H22: 1735 | I22: 20.54 | J22: 19.69 | K22: =IF(L22="", 0, L22) -> 49 | L22: 49 | M22: Yes | N22: =IF(E22 = "", "", E22-C22) -> 15 | O22: =IF(D22<C22,"Invalid","Valid") -> Valid | P22: =IF(N22>=(VLOOKUP(B22,Lembar2!$B$19:$C$24,2,FALSE)+7),"Delayed","Ontime") -> Ontime | Q22: =H22*I22 -> 35636.9 | R22: =H22*J22 -> 34162.15 | S22: =Q22-R22 -> 1474.75 | T22: =IF(P22="Ontime",1,0) -> 1
A23: PO-00022 | B23: Delta_Logistics | C23: 45136 | D23: =IF(E23="",C23+VLOOKUP(B23,Lembar2!$B$19:$C$24,2,FALSE),'Procurement Dataset'!E23) -> 45149 | E23: 45149 | F23: Raw Materials | G23: Delivered | H23: 1382 | I23: 24.93 | J23: 23.75 | K23: =IF(L23="", 0, L23) -> 0 | M23: Yes | N23: =IF(E23 = "", "", E23-C23) -> 13 | O23: =IF(D23<C23,"Invalid","Valid") -> Valid | P23: =IF(N23>=(VLOOKUP(B23,Lembar2!$B$19:$C$24,2,FALSE)+7),"Delayed","Ontime") -> Ontime | Q23: =H23*I23 -> 34453.26 | R23: =H23*J23 -> 32822.5 | S23: =Q23-R23 -> 1630.76 | T23: =IF(P23="Ontime",1,0) -> 1
A24: PO-00023 | B24: Epsilon_Group | C24: 44765 | D24: =IF(E24="",C24+VLOOKUP(B24,Lembar2!$B$19:$C$24,2,FALSE),'Procurement Dataset'!E24) -> 44781 | E24: 44781 | F24: MRO | G24: Delivered | H24: 819 | I24: 80.89 | J24: 77.03 | K24: =IF(L24="", 0, L24) -> 29 | L24: 29 | M24: Yes | N24: =IF(E24 = "", "", E24-C24) -> 16 | O24: =IF(D24<C24,"Invalid","Valid") -> Valid | P24: =IF(N24>=(VLOOKUP(B24,Lembar2!$B$19:$C$24,2,FALSE)+7),"Delayed","Ontime") -> Ontime | Q24: =H24*I24 -> 66248.91 | R24: =H24*J24 -> 63087.57 | S24: =Q24-R24 -> 3161.34 | T24: =IF(P24="Ontime",1,0) -> 1
A25: PO-00024 | B25: Beta_Supplies | C25: 45227 | D25: =IF(E25="",C25+VLOOKUP(B25,Lembar2!$B$19:$C$24,2,FALSE),'Procurement Dataset'!E25) -> 45233 | E25: 45233 | F25: Office Supplies | G25: Partially Delivered | H25: 393 | I25: 72.53 | J25: 66.31 | K25: =IF(L25="", 0, L25) -> 42 | L25: 42 | M25: No | N25: =IF(E25 = "", "", E25-C25) -> 6 | O25: =IF(D25<C25,"Invalid","Valid") -> Valid | P25: =IF(N25>=(VLOOKUP(B25,Lembar2!$B$19:$C$24,2,FALSE)+7),"Delayed","Ontime") -> Ontime | Q25: =H25*I25 -> 28504.29 | R25: =H25*J25 -> 26059.83 | S25: =Q25-R25 -> 2444.46 | T25: =IF(P25="Ontime",1,0) -> 1
A26: PO-00025 | B26: Beta_Supplies | C26: 45280 | D26: =IF(E26="",C26+VLOOKUP(B26,Lembar2!$B$19:$C$24,2,FALSE),'Procurement Dataset'!E26) -> 45292 | E26: 45292 | F26: MRO | G26: Delivered | H26: 1565 | I26: 21.3 | J26: 20.09 | K26: =IF(L26="", 0, L26) -> 161 | L26: 161 | M26: Yes | N26: =IF(E26 = "", "", E26-C26) -> 12 | O26: =IF(D26<C26,"Invalid","Valid") -> Valid | P26: =IF(N26>=(VLOOKUP(B26,Lembar2!$B$19:$C$24,2,FALSE)+7),"Delayed","Ontime") -> Ontime | Q26: =H26*I26 -> 33334.5 | R26: =H26*J26 -> 31440.85 | S26: =Q26-R26 -> 1893.65 | T26: =IF(P26="Ontime",1,0) -> 1
A27: PO-00026 | B27: Epsilon_Group | C27: 45120 | D27: =IF(E27="",C27+VLOOKUP(B27,Lembar2!$B$19:$C$24,2,FALSE),'Procurement Dataset'!E27) -> 45131 | E27: 45131 | F27: Packaging | G27: Delivered | H27: 1487 | I27: 19.15 | J27: 17.24 | K27: =IF(L27="", 0, L27) -> 0 | M27: Yes | N27: =IF(E27 = "", "", E27-C27) -> 11 | O27: =IF(D27<C27,"Invalid","Valid") -> Valid | P27: =IF(N27>=(VLOOKUP(B27,Lembar2!$B$19:$C$24,2,FALSE)+7),"Delayed","Ontime") -> Ontime | Q27: =H27*I27 -> 28476.05 | R27: =H27*J27 -> 25635.88 | S27: =Q27-R27 -> 2840.17 | T27: =IF(P27="Ontime",1,0) -> 1
A28: PO-00027 | B28: Alpha_Inc | C28: 44991 | D28: =IF(E28="",C28+VLOOKUP(B28,Lembar2!$B$19:$C$24,2,FALSE),'Procurement Dataset'!E28) -> 45011 | E28: 45011 | F28: MRO | G28: Delivered | H28: 855 | I28: 78.2 | J28: 67.16 | K28: =IF(L28="", 0, L28) -> 17 | L28: 17 | M28: Yes | N28: =IF(E28 = "", "", E28-C28) -> 20 | O28: =IF(D28<C28,"Invalid","Valid") -> Valid | P28: =IF(N28>=(VLOOKUP(B28,Lembar2!$B$19:$C$24,2,FALSE)+7),"Delayed","Ontime") -> Delayed | Q28: =H28*I28 -> 66861 | R28: =H28*J28 -> 57421.8 | S28: =Q28-R28 -> 9439.2 | T28: =IF(P28="Ontime",1,0) -> 0
A29: PO-00028 | B29: Epsilon_Group | C29: 44787 | D29: =IF(E29="",C29+VLOOKUP(B29,Lembar2!$B$19:$C$24,2,FALSE),'Procurement Dataset'!E29) -> 44796 | E29: 44796 | F29: Raw Materials | G29: Delivered | H29: 435 | I29: 17.13 | J29: 15.84 | K29: =IF(L29="", 0, L29) -> 8 | L29: 8 | M29: Yes | N29: =IF(E29 = "", "", E29-C29) -> 9 | O29: =IF(D29<C29,"Invalid","Valid") -> Valid | P29: =IF(N29>=(VLOOKUP(B29,Lembar2!$B$19:$C$24,2,FALSE)+7),"Delayed","Ontime") -> Ontime | Q29: =H29*I29 -> 7451.55 | R29: =H29*J29 -> 6890.4 | S29: =Q29-R29 -> 561.15 | T29: =IF(P29="Ontime",1,0) -> 1
A30: PO-00029 | B30: Delta_Logistics | C30: 45021 | D30: =IF(E30="",C30+VLOOKUP(B30,Lembar2!$B$19:$C$24,2,FALSE),'Procurement Dataset'!E30) -> 45038 | E30: 45038 | F30: MRO | G30: Delivered | H30: 1265 | I30: 90.26 | J30: 79.47 | K30: =IF(L30="", 0, L30) -> 187 | L30: 187 | M30: Yes | N30: =IF(E30 = "", "", E30-C30) -> 17 | O30: =IF(D30<C30,"Invalid","Valid") -> Valid | P30: =IF(N30>=(VLOOKUP(B30,Lembar2!$B$19:$C$24,2,FALSE)+7),"Delayed","Ontime") -> Ontime | Q30: =H30*I30 -> 114178.9 | R30: =H30*J30 -> 100529.55 | S30: =Q30-R30 -> 13649.35 | T30: =IF(P30="Ontime",1,0) -> 1
A31: PO-00030 | B31: Epsilon_Group | C31: 45165 | D31: =IF(E31="",C31+VLOOKUP(B31,Lembar2!$B$19:$C$24,2,FALSE),'Procurement Dataset'!E31) -> 45176 | F31: MRO | G31: Delivered | H31: 1005 | I31: 80.55 | J31: 73.31 | K31: =IF(L31="", 0, L31) -> 30 | L31: 30 | M31: Yes | N31: =IF(E31 = "", "", E31-C31) | O31: =IF(D31<C31,"Invalid","Valid") -> Valid | P31: =IF(N31>=(VLOOKUP(B31,Lembar2!$B$19:$C$24,2,FALSE)+7),"Delayed","Ontime") -> Delayed | Q31: =H31*I31 -> 80952.75 | R31: =H31*J31 -> 73676.55 | S31: =Q31-R31 -> 7276.2 | T31: =IF(P31="Ontime",1,0) -> 0
A32: PO-00031 | B32: Gamma_Co | C32: 44846 | D32: =IF(E32="",C32+VLOOKUP(B32,Lembar2!$B$19:$C$24,2,FALSE),'Procurement Dataset'!E32) -> 44860 | E32: 44860 | F32: Electronics | G32: Delivered | H32: 326 | I32: 18.1 | J32: 15.92 | K32: =IF(L32="", 0, L32) -> 0 | M32: No | N32: =IF(E32 = "", "", E32-C32) -> 14 | O32: =IF(D32<C32,"Invalid","Valid") -> Valid | P32: =IF(N32>=(VLOOKUP(B32,Lembar2!$B$19:$C$24,2,FALSE)+7),"Delayed","Ontime") -> Ontime | Q32: =H32*I32 -> 5900.6 | R32: =H32*J32 -> 5189.92 | S32: =Q32-R32 -> 710.68 | T32: =IF(P32="Ontime",1,0) -> 1
A33: PO-00032 | B33: Alpha_Inc | C33: 44568 | D33: =IF(E33="",C33+VLOOKUP(B33,Lembar2!$B$19:$C$24,2,FALSE),'Procurement Dataset'!E33) -> 44576 | E33: 44576 | F33: Office Supplies | G33: Delivered | H33: 1234 | I33: 17.64 | J33: 15.66 | K33: =IF(L33="", 0, L33) -> 26 | L33: 26 | M33: Yes | N33: =IF(E33 = "", "", E33-C33) -> 8 | O33: =IF(D33<C33,"Invalid","Valid") -> Valid | P33: =IF(N33>=(VLOOKUP(B33,Lembar2!$B$19:$C$24,2,FALSE)+7),"Delayed","Ontime") -> Ontime | Q33: =H33*I33 -> 21767.76 | R33: =H33*J33 -> 19324.44 | S33: =Q33-R33 -> 2443.32 | T33: =IF(P33="Ontime",1,0) -> 1
A34: PO-00033 | B34: Epsilon_Group | C34: 44725 | D34: =IF(E34="",C34+VLOOKUP(B34,Lembar2!$B$19:$C$24,2,FALSE),'Procurement Dataset'!E34) -> 44741 | E34: 44741 | F34: MRO | G34: Delivered | H34: 509 | I34: 101.27 | J34: 97.82 | K34: =IF(L34="", 0, L34) -> 19 | L34: 19 | M34: Yes | N34: =IF(E34 = "", "", E34-C34) -> 16 | O34: =IF(D34<C34,"Invalid","Valid") -> Valid | P34: =IF(N34>=(VLOOKUP(B34,Lembar2!$B$19:$C$24,2,FALSE)+7),"Delayed","Ontime") -> Ontime | Q34: =H34*I34 -> 51546.43 | R34: =H34*J34 -> 49790.38 | S34: =Q34-R34 -> 1756.05 | T34: =IF(P34="Ontime",1,0) -> 1
A35: PO-00034 | B35: Alpha_Inc | C35: 45276 | D35: =IF(E35="",C35+VLOOKUP(B35,Lembar2!$B$19:$C$24,2,FALSE),'Procurement Dataset'!E35) -> 45277 | E35: 45277 | F35: Packaging | G35: Delivered | H35: 1387 | I35: 48.71 | J35: 43.71 | K35: =IF(L35="", 0, L35) -> 27 | L35: 27 | M35: Yes | N35: =IF(E35 = "", "", E35-C35) -> 1 | O35: =IF(D35<C35,"Invalid","Valid") -> Valid | P35: =IF(N35>=(VLOOKUP(B35,Lembar2!$B$19:$C$24,2,FALSE)+7),"Delayed","Ontime") -> Ontime | Q35: =H35*I35 -> 67560.77 | R35: =H35*J35 -> 60625.77 | S35: =Q35-R35 -> 6935 | T35: =IF(P35="Ontime",1,0) -> 1
A36: PO-00035 | B36: Alpha_Inc | C36: 44994 | D36: =IF(E36="",C36+VLOOKUP(B36,Lembar2!$B$19:$C$24,2,FALSE),'Procurement Dataset'!E36) -> 45002 | E36: 45002 | F36: MRO | G36: Delivered | H36: 71 | I36: 46.39 | J36: 43.18 | K36: =IF(L36="", 0, L36) -> 0 | L36: 0 | M36: Yes | N36: =IF(E36 = "", "", E36-C36) -> 8 | O36: =IF(D36<C36,"Invalid","Valid") -> Valid | P36: =IF(N36>=(VLOOKUP(B36,Lembar2!$B$19:$C$24,2,FALSE)+7),"Delayed","Ontime") -> Ontime | Q36: =H36*I36 -> 3293.69 | R36: =H36*J36 -> 3065.78 | S36: =Q36-R36 -> 227.91 | T36: =IF(P36="Ontime",1,0) -> 1
A37: PO-00036 | B37: Epsilon_Group | C37: 44910 | D37: =IF(E37="",C37+VLOOKUP(B37,Lembar2!$B$19:$C$24,2,FALSE),'Procurement Dataset'!E37) -> 44918 | E37: 44918 | F37: Office Supplies | G37: Delivered | H37: 302 | I37: 87.73 | J37: 81.52 | K37: =IF(L37="", 0, L37) -> 9 | L37: 9 | M37: Yes | N37: =IF(E37 = "", "", E37-C37) -> 8 | O37: =IF(D37<C37,"Invalid","Valid") -> Valid | P37: =IF(N37>=(VLOOKUP(B37,Lembar2!$B$19:$C$24,2,FALSE)+7),"Delayed","Ontime") -> Ontime | Q37: =H37*I37 -> 26494.46 | R37: =H37*J37 -> 24619.04 | S37: =Q37-R37 -> 1875.42 | T37: =IF(P37="Ontime",1,0) -> 1
A38: PO-00037 | B38: Epsilon_Group | C38: 44846 | D38: =IF(E38="",C38+VLOOKUP(B38,Lembar2!$B$19:$C$24,2,FALSE),'Procurement Dataset'!E38) -> 44865 | E38: 44865 | F38: Office Supplies | G38: Pending | H38: 797 | I38: 99.54 | J38: 91.37 | K38: =IF(L38="", 0, L38) -> 18 | L38: 18 | M38: Yes | N38: =IF(E38 = "", "", E38-C38) -> 19 | O38: =IF(D38<C38,"Invalid","Valid") -> Valid | P38: =IF(N38>=(VLOOKUP(B38,Lembar2!$B$19:$C$24,2,FALSE)+7),"Delayed","Ontime") -> Delayed | Q38: =H38*I38 -> 79333.38 | R38: =H38*J38 -> 72821.89 | S38: =Q38-R38 -> 6511.49 | T38: =IF(P38="Ontime",1,0) -> 0
A39: PO-00038 | B39: Beta_Supplies | C39: 44721 | D39: =IF(E39="",C39+VLOOKUP(B39,Lembar2!$B$19:$C$24,2,FALSE),'Procurement Dataset'!E39) -> 44739 | E39: 44739 | F39: Office Supplies | G39: Pending | H39: 906 | I39: 101.21 | J39: 90.9 | K39: =IF(L39="", 0, L39) -> 94 | L39: 94 | M39: Yes | N39: =IF(E39 = "", "", E39-C39) -> 18 | O39: =IF(D39<C39,"Invalid","Valid") -> Valid | P39: =IF(N39>=(VLOOKUP(B39,Lembar2!$B$19:$C$24,2,FALSE)+7),"Delayed","Ontime") -> Ontime | Q39: =H39*I39 -> 91696.26 | R39: =H39*J39 -> 82355.4 | S39: =Q39-R39 -> 9340.86 | T39: =IF(P39="Ontime",1,0) -> 1
A40: PO-00039 | B40: Epsilon_Group | C40: 44782 | D40: =IF(E40="",C40+VLOOKUP(B40,Lembar2!$B$19:$C$24,2,FALSE),'Procurement Dataset'!E40) -> 44796 | E40: 44796 | F40: Office Supplies | G40: Delivered | H40: 1634 | I40: 80.53 | J40: 76.15 | K40: =IF(L40="", 0, L40) -> 50 | L40: 50 | M40: Yes | N40: =IF(E40 = "", "", E40-C40) -> 14 | O40: =IF(D40<C40,"Invalid","Valid") -> Valid | P40: =IF(N40>=(VLOOKUP(B40,Lembar2!$B$19:$C$24,2,FALSE)+7),"Delayed","Ontime") -> Ontime | Q40: =H40*I40 -> 131586.02 | R40: =H40*J40 -> 124429.1 | S40: =Q40-R40 -> 7156.92 | T40: =IF(P40="Ontime",1,0) -> 1
...

Sheet Lembar2
A1: DATA HANDLING
A3: CEK MISSING VALUE
A4: PO_ID | B4: =COUNTBLANK('Procurement Dataset'!A$1:A$778) -> 0
A5: Supplier | B5: =COUNTBLANK('Procurement Dataset'!B$1:B$778) -> 0
A6: Order_Date | B6: =COUNTBLANK('Procurement Dataset'!C$1:C$778) -> 0
A7: Delivery_Date | B7: =COUNTBLANK('Procurement Dataset'!E$1:E$778) -> 87
A8: Item_Category | B8: =COUNTBLANK('Procurement Dataset'!F$1:F$778) -> 0
A9: Order_Status | B9: =COUNTBLANK('Procurement Dataset'!G$1:G$778) -> 0
A10: Quantity | B10: =COUNTBLANK('Procurement Dataset'!H$1:H$778) -> 0
A11: Unit_Price | B11: =COUNTBLANK('Procurement Dataset'!I$1:I$778) -> 0
A12: Negotiated_Price | B12: =COUNTBLANK('Procurement Dataset'!J$1:J$778) -> 0
A13: Defective_Units | B13: =COUNTBLANK('Procurement Dataset'!L$1:L$778) -> 136
A14: Compliance | B14: =COUNTBLANK('Procurement Dataset'!M$1:M$778) -> 0
A15: HANDLING MISSING VALUE
A16: Delivery_Date | B16: Calculated lead_day | C16: delivered_date - order_date
B17: Median lead day
B18: Supplier | C18: med(lead_day)
B19: Alpha_Inc | C19: {=MEDIAN(IF('Procurement Dataset'!$B$2:$B$778=B19,'Procurement Dataset'!$N$2:$N$778))} -> 11
B20: Delta_Logistics | C20: {=MEDIAN(IF('Procurement Dataset'!$B$2:$B$778=B20,'Procurement Dataset'!$N$2:$N$778))} -> 11
B21: Gamma_Co | C21: {=MEDIAN(IF('Procurement Dataset'!$B$2:$B$778=B21,'Procurement Dataset'!$N$2:$N$778))} -> 10
B22: Beta_Supplies | C22: {=MEDIAN(IF('Procurement Dataset'!$B$2:$B$778=B22,'Procurement Dataset'!$N$2:$N$778))} -> 12
B23: Epsilon_Group | C23: {=MEDIAN(IF('Procurement Dataset'!$B$2:$B$778=B23,'Procurement Dataset'!$N$2:$N$778))} -> 11
B24: Alpha_Inc | C24: {=MEDIAN(IF('Procurement Dataset'!$B$2:$B$778=B24,'Procurement Dataset'!$N$2:$N$778))} -> 11
B25: Fill missing value with order_date + med(lead_day) sesuai supplier
A26: Defective_Units | B26: Fill missing value with 0 (tidak ada defective_unit)
A27: CEK DUPLIKAT | B27: Tidak ada duplikat
A28: DATA VALIDATION | B28: Cek apakah delivered date > order date => valid semua
A29: EDA | B29: Ontime_status | C29: if lead_day > mean_lead day + 7, delayed. Else ontime
B30: Total_amount | C30: quantity*unit_price
B31: Total_negotiated | C31: quantity*negotiated_price
B32: diff_price | C32: total_amount - total_negotiated
B33: is_ontime | C33: if ontime_status = ontime then 1, else 0
